<?xml version="1.0" encoding="UTF-8"?>
<!--
	NOTES:
	Units:
		Distance: m
		Angles: rad (only option)
		Mass: kg
		Inertia: kg*m^2
		
	Notes on intertia:
		-The inertias are calculated for uniform density using meshes with weights.
	
	Notes on finger q2:
		-The hand is a 4 bar linkage mechanism forming an 'X'. 4 bar linkages are not supported in the 
		urdf format. The motion of the second finger joint is fully defined by the motion of the first 
		finger joint. The calculation to find the index finger second joint angle given the first is provided
		in a matlab script elsewhere in this repository.
-->
<robot name="left_ability_hand">
   <link name="left_ability_hand_base">
      <visual name="wrist_mesh">
         <origin rpy="0 0 0" xyz="0 0 0" />
         <geometry>
            <mesh filename="package://ihmc_hands_ros2/meshes/abilityHand/wristmesh.STL" />
         </geometry>
      </visual>
      <inertial>
         <mass value="0.37511000" />
         <inertia ixx="3.76723021e-04" ixy="2.33895423e-06" ixz="-6.04325150e-06" iyy="4.67706269e-04" iyz="5.04572725e-05" izz="1.77650714e-04" />
         <origin xyz="-6.54520000e-04 -5.98838000e-03 5.07726500e-02" rpy="0 0 0" />
      </inertial>
      <visual name="palm_mesh">
         <origin rpy="3.14148426 0.08848813 3.14036612" xyz="24.0476665e-3 3.78124745e-3 32.32964923e-3" />
         <geometry>
            <mesh filename="package://ihmc_hands_ros2/meshes/abilityHand/FB_palm_ref.STL" />
         </geometry>
      </visual>
      <collision name="palm_mesh_coll">
         <origin rpy="3.14148426 0.08848813 3.14036612" xyz="24.0476665e-3 3.78124745e-3 32.32964923e-3" />
         <geometry>
            <mesh filename="package://ihmc_hands_ros2/meshes/abilityHand/palm_hull.STL" />
         </geometry>
      </collision>
   </link>
   <link name="left_ability_hand_index_L1">
      <inertial>
         <mass value="0.00636000" />
         <inertia ixx="2.85169621e-07" ixy="1.21454801e-08" ixz="2.02098452e-09" iyy="9.77683041e-07" iyz="-2.87547802e-10" izz="1.05411544e-06" />
         <origin xyz="1.77549969e-02 -2.13867669e-04 -2.02851433e-05" rpy="0 0 0" />
      </inertial>
      <visual name="index_mesh_1">
         <origin xyz="0 0 0" rpy="0 0 0" />
         <geometry>
            <mesh filename="package://ihmc_hands_ros2/meshes/abilityHand/idx-F1.STL" />
         </geometry>
      </visual>
      <collision name="index_mesh_coll_1">
         <origin rpy="0 0 0.0844739" xyz="0.0384727 0.0032577 0" />
         <geometry>
            <mesh filename="package://ihmc_hands_ros2/meshes/abilityHand/idx-F1-hull.STL" />
         </geometry>
      </collision>
   </link>
   <link name="left_ability_hand_index_L2">
      <inertial>
         <mass value="0.00600000" />
         <inertia ixx="4.06340451e-07" ixy="3.99862338e-07" ixz="-1.91966414e-09" iyy="9.13745257e-07" iyz="8.96846813e-10" izz="1.13382499e-06" />
         <origin xyz="1.52723400e-02 -1.00039197e-02 -3.11063902e-05" rpy="0 0 0" />
      </inertial>
      <visual name="index_mesh_2">
         <origin rpy="0 0 0" xyz="0 0 0" />
         <geometry>
            <mesh filename="package://ihmc_hands_ros2/meshes/abilityHand/idx-F2.STL" />
         </geometry>
      </visual>
      <collision name="index_mesh_coll_2">
         <origin rpy="0 0 0" xyz="0.0091241 0 0" />
         <geometry>
            <mesh filename="package://ihmc_hands_ros2/meshes/abilityHand/idx-F2-hull.STL" />
         </geometry>
      </collision>
   </link>
   <joint name="left_ability_hand_index_q1" type="revolute">
      <parent link="left_ability_hand_base" />
      <child link="left_ability_hand_index_L1" />
      <origin xyz="0.028 -0.009 0.096" rpy="1.470 -1.317 -1.352" />
      <axis xyz="0 0 1" />
      <limit lower="0" upper="1.74" effort="6.0" velocity="8.0677777442" />
      <!-- angles in rad, efforts in N-m, velocity in rad/s -->
      <dynamics damping="0.001" friction="0.001" />
      <!-- Friction coefficient is not from quantitative measurement -->
   </joint>
   <joint name="left_ability_hand_index_q2" type="revolute">
      <parent link="left_ability_hand_index_L1" />
      <child link="left_ability_hand_index_L2" />
      <origin xyz="38.472723e-3 3.257695e-3 0.000000e-3" rpy="0 0 0.084474" />
      <axis xyz="0 0 1" />
      <limit lower="0.766" upper="2.61" effort="6.0" velocity="8.0677777442" />
      <!-- angles in rad, efforts in N-m, velocity in rad/s -->
      <dynamics damping="0.001" friction="0.001" />
      <!-- Friction coefficient is not from quantitative measurement -->
      <mimic joint="index_q1" multiplier="1.05851325" offset="0.72349796" />
   </joint>
   <link name="left_ability_hand_index_anchor" />
   <joint name="left_ability_hand_idx_anchor" type="fixed">
      <parent link="left_ability_hand_index_L2" />
      <child link="left_ability_hand_index_anchor" />
      <origin rpy="0 0 0" xyz="31.5541e-3  -10.44e-3 0.14e-3" />
   </joint>
   <link name="left_ability_hand_fsr0" />
   <joint name="left_ability_hand_fsr0" type="fixed">
      <parent link="left_ability_hand_index_L2" />
      <child link="left_ability_hand_fsr0" />
      <origin rpy="3.14 0 -0.1848" xyz="0.02556 -0.01391 -0.00435" />
   </joint>
   <link name="left_ability_hand_fsr1" />
   <joint name="left_ability_hand_fsr1" type="fixed">
      <parent link="left_ability_hand_index_L2" />
      <child link="left_ability_hand_fsr1" />
      <origin rpy="-1.5708 0.0 -0.2316" xyz="0.02517 -0.01110 -0.00000" />
   </joint>
   <link name="left_ability_hand_fsr2" />
   <joint name="left_ability_hand_fsr2" type="fixed">
      <parent link="left_ability_hand_index_L2" />
      <child link="left_ability_hand_fsr2" />
      <origin rpy="0.0 0.0 -0.1848036056311012" xyz="0.02556 -0.01391 0.00435" />
   </joint>
   <link name="left_ability_hand_fsr3" />
   <joint name="left_ability_hand_fsr3" type="fixed">
      <parent link="left_ability_hand_index_L2" />
      <child link="left_ability_hand_fsr3" />
      <origin rpy="3.14159 0.00000 -0.57092" xyz="0.01310 -0.00943 -0.00435" />
   </joint>
   <link name="left_ability_hand_fsr4" />
   <joint name="left_ability_hand_fsr4" type="fixed">
      <parent link="left_ability_hand_index_L2" />
      <child link="left_ability_hand_fsr4" />
      <origin rpy="0.00000 0.00000 -0.57199" xyz="0.01310 -0.00943 0.00435" />
   </joint>
   <link name="left_ability_hand_fsr5" />
   <joint name="left_ability_hand_fsr5" type="fixed">
      <parent link="left_ability_hand_index_L2" />
      <child link="left_ability_hand_fsr5" />
      <origin rpy="-2.66907 -1.57080 0.00000" xyz="0.03142 -0.01438 0.00000" />
   </joint>
   <link name="left_ability_hand_middle_L1">
      <inertial>
         <mass value="0.00636000" />
         <inertia ixx="2.85169621e-07" ixy="1.21454801e-08" ixz="2.02098452e-09" iyy="9.77683041e-07" iyz="-2.87547802e-10" izz="1.05411544e-06" />
         <origin xyz="1.77549969e-02 -2.13867669e-04 -2.02851433e-05" rpy="0 0 0" />
      </inertial>
      <visual name="middle_mesh_1">
         <origin rpy="0 0 0" xyz="0 0 0" />
         <geometry>
            <mesh filename="package://ihmc_hands_ros2/meshes/abilityHand/idx-F1.STL" />
         </geometry>
      </visual>
      <collision name="middle_mesh_coll_1">
         <origin rpy="0 0 0.0844739" xyz="0.0384727 0.0032577 0" />
         <geometry>
            <mesh filename="package://ihmc_hands_ros2/meshes/abilityHand/idx-F1-hull.STL" />
         </geometry>
      </collision>
   </link>
   <link name="left_ability_hand_middle_L2">
      <inertial>
         <mass value="0.00600000" />
         <inertia ixx="4.06340451e-07" ixy="3.99862338e-07" ixz="-1.91966414e-09" iyy="9.13745257e-07" iyz="8.96846813e-10" izz="1.13382499e-06" />
         <origin xyz="1.52723400e-02 -1.00039197e-02 -3.11063902e-05" rpy="0 0 0" />
      </inertial>
      <visual name="middle_mesh_2">
         <origin rpy="0 0 0" xyz="0 0 0" />
         <geometry>
            <mesh filename="package://ihmc_hands_ros2/meshes/abilityHand/idx-F2.STL" />
         </geometry>
      </visual>
      <collision name="middle_mesh_coll_2">
         <origin rpy="0 0 0" xyz="0.0091241 0 0" />
         <geometry>
            <mesh filename="package://ihmc_hands_ros2/meshes/abilityHand/idx-F2-hull.STL" />
         </geometry>
      </collision>
   </link>
   <joint name="left_ability_hand_middle_q1" type="revolute">
      <parent link="left_ability_hand_base" />
      <child link="left_ability_hand_middle_L1" />
      <origin xyz="0.008 -0.012 0.099" rpy="1.629 -1.322 -1.583" />
      <limit lower="0" upper="1.74" effort="6.0" velocity="8.0677777442" />
      <!-- angles in rad, efforts in N-m, velocity in rad/s -->
      <dynamics damping="0.001" friction="0.001" />
      <!-- Friction coefficient is not from quantitative measurement -->
      <axis xyz="0 0 1" />
   </joint>
   <joint name="left_ability_hand_middle_q2" type="revolute">
      <parent link="left_ability_hand_middle_L1" />
      <child link="left_ability_hand_middle_L2" />
      <origin xyz="38.472723e-3 3.257695e-3 0.000000" rpy="0 0 0.084474" />
      <axis xyz="0 0 1" />
      <limit lower="0.766" upper="2.61" effort="6.0" velocity="8.0677777442" />
      <!-- angles in rad, efforts in N-m, velocity in rad/s -->
      <dynamics damping="0.001" friction="0.001" />
      <!-- Friction coefficient is not from quantitative measurement -->
      <mimic joint="middle_q1" multiplier="1.05851325" offset="0.72349796" />
   </joint>
   <link name="left_ability_hand_middle_anchor" />
   <joint name="left_ability_hand_mid_anchor" type="fixed">
      <parent link="left_ability_hand_middle_L2" />
      <child link="left_ability_hand_middle_anchor" />
      <origin rpy="0 0 0" xyz="31.5541e-3  -10.44e-3 0.14e-3" />
   </joint>
   <link name="left_ability_hand_fsr6" />
   <joint name="left_ability_hand_fsr6" type="fixed">
      <parent link="left_ability_hand_middle_L2" />
      <child link="left_ability_hand_fsr6" />
      <origin rpy="3.14 0 -0.1848" xyz="0.02556 -0.01391 -0.00435" />
   </joint>
   <link name="left_ability_hand_fsr7" />
   <joint name="left_ability_hand_fsr7" type="fixed">
      <parent link="left_ability_hand_middle_L2" />
      <child link="left_ability_hand_fsr7" />
      <origin rpy="-1.5708 0.0 -0.2316" xyz="0.02517 -0.01110 -0.00000" />
   </joint>
   <link name="left_ability_hand_fsr8" />
   <joint name="left_ability_hand_fsr8" type="fixed">
      <parent link="left_ability_hand_middle_L2" />
      <child link="left_ability_hand_fsr8" />
      <origin rpy="0.0 0.0 -0.1848036056311012" xyz="0.02556 -0.01391 0.00435" />
   </joint>
   <link name="left_ability_hand_fsr9" />
   <joint name="left_ability_hand_fsr9" type="fixed">
      <parent link="left_ability_hand_middle_L2" />
      <child link="left_ability_hand_fsr9" />
      <origin rpy="3.14159 0.00000 -0.57092" xyz="0.01310 -0.00943 -0.00435" />
   </joint>
   <link name="left_ability_hand_fsr10" />
   <joint name="left_ability_hand_fsr10" type="fixed">
      <parent link="left_ability_hand_middle_L2" />
      <child link="left_ability_hand_fsr10" />
      <origin rpy="0.00000 0.00000 -0.57199" xyz="0.01310 -0.00943 0.00435" />
   </joint>
   <link name="left_ability_hand_fsr11" />
   <joint name="left_ability_hand_fsr11" type="fixed">
      <parent link="left_ability_hand_middle_L2" />
      <child link="left_ability_hand_fsr11" />
      <origin rpy="-2.66907 -1.57080 0.00000" xyz="0.03142 -0.01438 0.00000" />
   </joint>
   <link name="left_ability_hand_ring_L1">
      <inertial>
         <mass value="0.00636000" />
         <inertia ixx="2.85169621e-07" ixy="1.21454801e-08" ixz="2.02098452e-09" iyy="9.77683041e-07" iyz="-2.87547802e-10" izz="1.05411544e-06" />
         <origin xyz="1.77549969e-02 -2.13867669e-04 -2.02851433e-05" rpy="0 0 0" />
      </inertial>
      <visual name="ring_mesh_1">
         <origin rpy="0 0 0" xyz="0 0 0" />
         <geometry>
            <mesh filename="package://ihmc_hands_ros2/meshes/abilityHand/idx-F1.STL" />
         </geometry>
      </visual>
      <collision name="ring_mesh_coll_1">
         <origin rpy="0 0 0.0844739" xyz="0.0384727 0.0032577 0" />
         <geometry>
            <mesh filename="package://ihmc_hands_ros2/meshes/abilityHand/idx-F1-hull.STL" />
         </geometry>
      </collision>
   </link>
   <link name="left_ability_hand_ring_L2">
      <inertial>
         <mass value="0.00600000" />
         <inertia ixx="4.06340451e-07" ixy="3.99862338e-07" ixz="-1.91966414e-09" iyy="9.13745257e-07" iyz="8.96846813e-10" izz="1.13382499e-06" />
         <origin xyz="1.52723400e-02 -1.00039197e-02 -3.11063902e-05" rpy="0 0 0" />
      </inertial>
      <visual name="ring_mesh_2">
         <origin rpy="0 0 0" xyz="0 0 0" />
         <geometry>
            <mesh filename="package://ihmc_hands_ros2/meshes/abilityHand/idx-F2.STL" />
         </geometry>
      </visual>
      <collision name="ring_mesh_coll_2">
         <origin rpy="0 0 0" xyz="0.0091241 0 0" />
         <geometry>
            <mesh filename="package://ihmc_hands_ros2/meshes/abilityHand/idx-F2-hull.STL" />
         </geometry>
      </collision>
   </link>
   <joint name="left_ability_hand_ring_q1" type="revolute">
      <parent link="left_ability_hand_base" />
      <child link="left_ability_hand_ring_L1" />
      <origin xyz="-0.012 -0.010 0.097" rpy="1.780 -1.315 -1.811" />
      <limit lower="0" upper="1.74" effort="6.0" velocity="8.0677777442" />
      <!-- angles in rad, efforts in N-m, velocity in rad/s -->
      <dynamics damping="0.001" friction="0.001" />
      <!-- Friction coefficient is not from quantitative measurement -->
      <axis xyz="0 0 1" />
   </joint>
   <joint name="left_ability_hand_ring_q2" type="revolute">
      <parent link="left_ability_hand_ring_L1" />
      <child link="left_ability_hand_ring_L2" />
      <origin xyz="38.472723e-3 3.257695e-3 0.000000" rpy="0 0 0.084474" />
      <axis xyz="0 0 1" />
      <limit lower="0.766" upper="2.61" effort="6.0" velocity="8.0677777442" />
      <!-- angles in rad, efforts in N-m, velocity in rad/s -->
      <dynamics damping="0.001" friction="0.001" />
      <!-- Friction coefficient is not from quantitative measurement -->
      <mimic joint="ring_q1" multiplier="1.05851325" offset="0.72349796" />
   </joint>
   <link name="left_ability_hand_ring_anchor" />
   <joint name="left_ability_hand_rng_anchor" type="fixed">
      <parent link="left_ability_hand_ring_L2" />
      <child link="left_ability_hand_ring_anchor" />
      <origin rpy="0 0 0" xyz="31.5541e-3  -10.44e-3 0.14e-3" />
   </joint>
   <link name="left_ability_hand_fsr12" />
   <joint name="left_ability_hand_fsr12" type="fixed">
      <parent link="left_ability_hand_ring_L2" />
      <child link="left_ability_hand_fsr12" />
      <origin rpy="3.14 0 -0.1848" xyz="0.02556 -0.01391 -0.00435" />
   </joint>
   <link name="left_ability_hand_fsr13" />
   <joint name="left_ability_hand_fsr13" type="fixed">
      <parent link="left_ability_hand_ring_L2" />
      <child link="left_ability_hand_fsr13" />
      <origin rpy="-1.5708 0.0 -0.2316" xyz="0.02517 -0.01110 -0.00000" />
   </joint>
   <link name="left_ability_hand_fsr14" />
   <joint name="left_ability_hand_fsr14" type="fixed">
      <parent link="left_ability_hand_ring_L2" />
      <child link="left_ability_hand_fsr14" />
      <origin rpy="0.0 0.0 -0.1848036056311012" xyz="0.02556 -0.01391 0.00435" />
   </joint>
   <link name="left_ability_hand_fsr15" />
   <joint name="left_ability_hand_fsr15" type="fixed">
      <parent link="left_ability_hand_ring_L2" />
      <child link="left_ability_hand_fsr15" />
      <origin rpy="3.14159 0.00000 -0.57092" xyz="0.01310 -0.00943 -0.00435" />
   </joint>
   <link name="left_ability_hand_fsr16" />
   <joint name="left_ability_hand_fsr16" type="fixed">
      <parent link="left_ability_hand_ring_L2" />
      <child link="left_ability_hand_fsr16" />
      <origin rpy="0.00000 0.00000 -0.57199" xyz="0.01310 -0.00943 0.00435" />
   </joint>
   <link name="left_ability_hand_fsr17" />
   <joint name="left_ability_hand_fsr17" type="fixed">
      <parent link="left_ability_hand_ring_L2" />
      <child link="left_ability_hand_fsr17" />
      <origin rpy="-2.66907 -1.57080 0.00000" xyz="0.03142 -0.01438 0.00000" />
   </joint>
   <link name="left_ability_hand_pinky_L1">
      <inertial>
         <mass value="0.00636000" />
         <inertia ixx="2.85169621e-07" ixy="1.21454801e-08" ixz="2.02098452e-09" iyy="9.77683041e-07" iyz="-2.87547802e-10" izz="1.05411544e-06" />
         <origin xyz="1.77549969e-02 -2.13867669e-04 -2.02851433e-05" rpy="0 0 0" />
      </inertial>
      <visual name="pinky_mesh_1">
         <origin rpy="0 0 0" xyz="0 0 0" />
         <geometry>
            <mesh filename="package://ihmc_hands_ros2/meshes/abilityHand/idx-F1.STL" />
         </geometry>
      </visual>
      <collision name="pinky_mesh_coll_1">
         <origin rpy="0 0 0.0844739" xyz="0.0384727 0.0032577 0" />
         <geometry>
            <mesh filename="package://ihmc_hands_ros2/meshes/abilityHand/idx-F1-hull.STL" />
         </geometry>
      </collision>
   </link>
   <link name="left_ability_hand_pinky_L2">
      <inertial>
         <mass value="0.00600000" />
         <inertia ixx="3.07970159e-07" ixy="2.80921010e-07" ixz="-2.72117073e-09" iyy="7.40775495e-07" iyz="1.08144438e-09" izz="8.93728844e-07" />
         <origin xyz="1.33249215e-02 -8.15894775e-03 -4.07689501e-05" rpy="0 0 0" />
      </inertial>
      <visual name="pinky_mesh_2">
         <origin rpy="0 0 0" xyz="0 0 0" />
         <geometry>
            <mesh filename="package://ihmc_hands_ros2/meshes/abilityHand/idx-F2.STL" />
         </geometry>
      </visual>
      <collision name="pinky_mesh_coll_2">
         <origin rpy="0 0 0" xyz="0.0091241 0 0" />
         <geometry>
            <mesh filename="package://ihmc_hands_ros2/meshes/abilityHand/idx-F2-hull.STL" />
         </geometry>
      </collision>
   </link>
   <joint name="left_ability_hand_pinky_q1" type="revolute">
      <parent link="left_ability_hand_base" />
      <child link="left_ability_hand_pinky_L1" />
      <origin xyz="-0.031 -0.007 0.091" rpy="1.731 -1.315 -1.828" />
      <limit lower="0" upper="1.74" effort="6.0" velocity="8.0677777442" />
      <!-- angles in rad, efforts in N-m, velocity in rad/s -->
      <dynamics damping="0.001" friction="0.001" />
      <!-- Friction coefficient is not from quantitative measurement -->
      <axis xyz="0 0 1" />
   </joint>
   <joint name="left_ability_hand_pinky_q2" type="revolute">
      <parent link="left_ability_hand_pinky_L1" />
      <child link="left_ability_hand_pinky_L2" />
      <origin xyz="38.472723e-3 3.257695e-3 0.000000" rpy="0 0 0.084474" />
      <limit lower="0.766" upper="2.61" effort="6.0" velocity="8.0677777442" />
      <!-- angles in rad, efforts in N-m, velocity in rad/s -->
      <dynamics damping="0.001" friction="0.001" />
      <!-- Friction coefficient is not from quantitative measurement -->
      <axis xyz="0 0 1" />
      <mimic joint="pinky_q1" multiplier="1.05851325" offset="0.72349796" />
   </joint>
   <link name="left_ability_hand_pinky_anchor" />
   <joint name="left_ability_hand_pnky_anchor" type="fixed">
      <parent link="left_ability_hand_pinky_L2" />
      <child link="left_ability_hand_pinky_anchor" />
      <origin rpy="0 0 0" xyz="31.5541e-3  -10.44e-3 0.14e-3" />
   </joint>
   <link name="left_ability_hand_fsr18" />
   <joint name="left_ability_hand_fsr18" type="fixed">
      <parent link="left_ability_hand_pinky_L2" />
      <child link="left_ability_hand_fsr18" />
      <origin rpy="3.14 0 -0.1848" xyz="0.02556 -0.01391 -0.00435" />
   </joint>
   <link name="left_ability_hand_fsr19" />
   <joint name="left_ability_hand_fsr19" type="fixed">
      <parent link="left_ability_hand_pinky_L2" />
      <child link="left_ability_hand_fsr19" />
      <origin rpy="-1.5708 0.0 -0.2316" xyz="0.02517 -0.01110 -0.00000" />
   </joint>
   <link name="left_ability_hand_fsr20" />
   <joint name="left_ability_hand_fsr20" type="fixed">
      <parent link="left_ability_hand_pinky_L2" />
      <child link="left_ability_hand_fsr20" />
      <origin rpy="0.0 0.0 -0.1848036056311012" xyz="0.02556 -0.01391 0.00435" />
   </joint>
   <link name="left_ability_hand_fsr21" />
   <joint name="left_ability_hand_fsr21" type="fixed">
      <parent link="left_ability_hand_pinky_L2" />
      <child link="left_ability_hand_fsr21" />
      <origin rpy="3.14159 0.00000 -0.57092" xyz="0.01310 -0.00943 -0.00435" />
   </joint>
   <link name="left_ability_hand_fsr22" />
   <joint name="left_ability_hand_fsr22" type="fixed">
      <parent link="left_ability_hand_pinky_L2" />
      <child link="left_ability_hand_fsr22" />
      <origin rpy="0.00000 0.00000 -0.57199" xyz="0.01310 -0.00943 0.00435" />
   </joint>
   <link name="left_ability_hand_fsr23" />
   <joint name="left_ability_hand_fsr23" type="fixed">
      <parent link="left_ability_hand_pinky_L2" />
      <child link="left_ability_hand_fsr23" />
      <origin rpy="-2.66907 -1.57080 0.00000" xyz="0.03142 -0.01438 0.00000" />
   </joint>
   <link name="left_ability_hand_thumb_L1">
      <inertial>
         <mass value="0.00200000" />
         <inertia ixx="1.18180125e-07" ixy="2.01333778e-08" ixz="6.82164634e-08" iyy="2.49626759e-07" iyz="-8.51306376e-09" izz="2.02510886e-07" />
         <origin xyz="1.43350200e-02 -1.88501000e-03 -5.04062000e-03" rpy="0 0 0" />
      </inertial>
      <visual name="thumb_mesh_1">
         <origin rpy="0 0 0" xyz="0 0 0" />
         <geometry>
            <mesh filename="package://ihmc_hands_ros2/meshes/abilityHand/thumb-F1.STL" />
         </geometry>
      </visual>
      <collision name="thumb_coll_mesh_1">
         <origin rpy="-1.83260 0 0" xyz="0.02783 0 -0.01475" />
         <geometry>
            <mesh filename="package://ihmc_hands_ros2/meshes/abilityHand/thumb-F1-hull.STL" />
         </geometry>
      </collision>
   </link>
   <link name="left_ability_hand_thumb_L2">
      <inertial>
         <mass value="0.06000000" />
         <inertia ixx="8.10858595e-06" ixy="-7.50865361e-06" ixz="-6.23775212e-08" iyy="2.16060962e-05" iyz="-1.00035818e-07" izz="2.58546356e-05" />
         <origin xyz="2.77624500e-02 5.62171000e-03 -4.10855000e-03" rpy="0 0 0" />
      </inertial>
      <visual name="thumb_mesh_2">
         <origin rpy="0 0 0" xyz="0 0 0" />
         <geometry>
            <mesh filename="package://ihmc_hands_ros2/meshes/abilityHand/thumb-F2-left.STL" />
         </geometry>
      </visual>
      <collision name="thumb_hull_mesh_2">
         <origin rpy="3.14159 0 0.34383" xyz="0.06519 0.02334 -0.00393" />
         <geometry>
            <mesh filename="package://ihmc_hands_ros2/meshes/abilityHand/thumb-F2-hull.STL" />
         </geometry>
      </collision>
   </link>
   <joint name="left_ability_hand_thumb_q1" type="revolute">
      <parent link="left_ability_hand_base" />
      <child link="left_ability_hand_thumb_L1" />
      <origin xyz="24.0476665e-3 3.78124745e-3 32.32964923e-3" rpy="-3.1250458 -0.08693131 -0.1883423" />
      <axis xyz="0 0 1" />
      <limit lower="-1.74" upper="0" effort="1.2" velocity="40.338888721" />
      <!-- angles in rad, efforts in N-m, velocity in rad/s -->
      <dynamics damping="0.001" friction="0.001" />
      <!-- Friction coefficient is not from quantitative measurement -->
   </joint>
   <joint name="left_ability_hand_thumb_q2" type="revolute">
      <parent link="left_ability_hand_thumb_L1" />
      <child link="left_ability_hand_thumb_L2" />
      <origin xyz="27.8283501e-3 0 -14.7507000e-3" rpy="4.450589592585541 0 0" />
      <axis xyz="0 0 1" />
      <limit lower="0" upper="1.74" effort="6.0" velocity="8.0677777442" />
      <!-- angles in rad, efforts in N-m, velocity in rad/s -->
      <dynamics damping="0.001" friction="0.001" />
      <!-- Friction coefficient is not from quantitative measurement -->
   </joint>
   <link name="left_ability_hand_thumb_anchor" />
   <joint name="left_ability_hand_thmb_anchor" type="fixed">
      <parent link="left_ability_hand_thumb_L2" />
      <child link="left_ability_hand_thumb_anchor" />
      <origin rpy="0 0 0" xyz="52.0012259e-3  28.0086971e-3 -.884835778e-3" />
   </joint>
   <link name="left_ability_hand_fsr24" />
   <joint name="left_ability_hand_fsr24" type="fixed">
      <parent link="left_ability_hand_thumb_L2" />
      <child link="left_ability_hand_fsr24" />
      <origin rpy="-2.29074 0.00001 0.41769" xyz="0.04747 0.01988 -0.00874" />
   </joint>
   <link name="left_ability_hand_fsr25" />
   <joint name="left_ability_hand_fsr25" type="fixed">
      <parent link="left_ability_hand_thumb_L2" />
      <child link="left_ability_hand_fsr25" />
      <origin rpy="-1.30899 0.00001 0.41769" xyz="0.04721 0.02124 -0.00106" />
   </joint>
   <link name="left_ability_hand_fsr26" />
   <joint name="left_ability_hand_fsr26" type="fixed">
      <parent link="left_ability_hand_thumb_L2" />
      <child link="left_ability_hand_fsr26" />
      <origin rpy="-0.32726 0.00001 0.41769" xyz="0.04896 0.01654 0.00491" />
   </joint>
   <link name="left_ability_hand_fsr27" />
   <joint name="left_ability_hand_fsr27" type="fixed">
      <parent link="left_ability_hand_thumb_L2" />
      <child link="left_ability_hand_fsr27" />
      <origin rpy="-2.29074 0.00001 0.41769" xyz="0.03739 0.01536 -0.00879" />
   </joint>
   <link name="left_ability_hand_fsr28" />
   <joint name="left_ability_hand_fsr28" type="fixed">
      <parent link="left_ability_hand_thumb_L2" />
      <child link="left_ability_hand_fsr28" />
      <origin rpy="-0.32726 0.00001 0.41769" xyz="0.03888 0.01200 0.00494" />
   </joint>
   <link name="left_ability_hand_fsr29" />
   <joint name="left_ability_hand_fsr29" type="fixed">
      <parent link="left_ability_hand_thumb_L2" />
      <child link="left_ability_hand_fsr29" />
      <origin rrpy="-1.39339 0.19354 -0.40280" xyz="0.05591 0.02160 -0.00192" />
   </joint>
</robot>
